2022-11-22 15:31:00,379 INFO    MainThread:9824 [wandb_setup.py:_flush():68] Configure stats pid to 9824
2022-11-22 15:31:00,379 INFO    MainThread:9824 [wandb_setup.py:_flush():68] Loading settings from C:\Users\User\.config\wandb\settings
2022-11-22 15:31:00,380 INFO    MainThread:9824 [wandb_setup.py:_flush():68] Loading settings from c:\Users\User\Documents\rpoditela\Intra\autoencoder\wandb\settings
2022-11-22 15:31:00,380 INFO    MainThread:9824 [wandb_setup.py:_flush():68] Loading settings from environment variables: {'_require_service': 'True'}
2022-11-22 15:31:00,380 INFO    MainThread:9824 [wandb_setup.py:_flush():68] Inferring run settings from compute environment: {'program': '<python with no main file>'}
2022-11-22 15:31:00,387 INFO    MainThread:9824 [wandb_init.py:_log_setup():476] Logging user logs to c:\Users\User\Documents\rpoditela\Intra\autoencoder\wandb\run-20221122_153100-20si4v5s\logs\debug.log
2022-11-22 15:31:00,387 INFO    MainThread:9824 [wandb_init.py:_log_setup():477] Logging internal logs to c:\Users\User\Documents\rpoditela\Intra\autoencoder\wandb\run-20221122_153100-20si4v5s\logs\debug-internal.log
2022-11-22 15:31:00,387 INFO    MainThread:9824 [wandb_init.py:init():516] calling init triggers
2022-11-22 15:31:00,387 INFO    MainThread:9824 [wandb_init.py:init():519] wandb.init called with sweep_config: {}
config: {'learning_rate': 0.0001, 'epochs': 6000, 'batch_size': 1, 'dataset': ['ArteryObjAN1-17-55.dat'], 'number of trees': 1, 'optim': Adam (
Parameter Group 0
    amsgrad: False
    betas: (0.9, 0.999)
    eps: 1e-08
    lr: 0.0001
    maximize: False
    weight_decay: 0
)}
2022-11-22 15:31:00,387 INFO    MainThread:9824 [wandb_init.py:init():535] re-initializing run, found existing run on stack: 2crjelxb
2022-11-22 15:31:00,389 INFO    MainThread:9824 [wandb_run.py:_finish():1746] finishing run paufeldman/autoencoder3/2crjelxb
2022-11-22 15:31:00,390 INFO    MainThread:9824 [jupyter.py:save_history():448] not saving jupyter history
2022-11-22 15:31:00,390 INFO    MainThread:9824 [jupyter.py:save_ipynb():378] not saving jupyter notebook
2022-11-22 15:31:00,390 INFO    MainThread:9824 [wandb_init.py:_jupyter_teardown():408] cleaning up jupyter logic
2022-11-22 15:31:00,390 INFO    MainThread:9824 [wandb_run.py:_atexit_cleanup():1949] got exitcode: 0
2022-11-22 15:31:00,391 INFO    MainThread:9824 [wandb_run.py:_restore():1932] restore
2022-11-22 15:31:00,391 INFO    MainThread:9824 [wandb_run.py:_restore():1938] restore done
2022-11-22 15:31:56,867 INFO    MainThread:9824 [wandb_init.py:init():569] starting backend
2022-11-22 15:31:56,867 INFO    MainThread:9824 [wandb_init.py:init():573] setting up manager
2022-11-22 15:31:56,877 INFO    MainThread:9824 [backend.py:_multiprocessing_setup():102] multiprocessing start_methods=spawn, using: spawn
2022-11-22 15:31:56,881 INFO    MainThread:9824 [wandb_init.py:init():580] backend started and connected
2022-11-22 15:31:56,895 INFO    MainThread:9824 [wandb_run.py:_label_probe_notebook():1113] probe notebook
2022-11-22 15:31:56,895 INFO    MainThread:9824 [wandb_run.py:_label_probe_notebook():1123] Unable to probe notebook: 'NoneType' object has no attribute 'get'
2022-11-22 15:31:56,895 INFO    MainThread:9824 [wandb_init.py:init():658] updated telemetry
2022-11-22 15:31:56,931 INFO    MainThread:9824 [wandb_init.py:init():693] communicating run to backend with 60 second timeout
2022-11-22 15:32:00,451 WARNING MsgRouterThr:9824 [router.py:message_loop():77] message_loop has been closed
2022-11-22 15:32:00,451 WARNING MsgRouterThr:9824 [router.py:message_loop():77] message_loop has been closed
2022-11-22 15:32:02,004 ERROR   MainThread:9824 [wandb_init.py:init():1105] error
Traceback (most recent call last):
  File "c:\Users\User\anaconda3\envs\py_torc\lib\site-packages\wandb\sdk\wandb_init.py", line 1078, in init
    run = wi.init()
  File "c:\Users\User\anaconda3\envs\py_torc\lib\site-packages\wandb\sdk\wandb_init.py", line 697, in init
    result = handle.wait(
  File "c:\Users\User\anaconda3\envs\py_torc\lib\site-packages\wandb\sdk\lib\mailbox.py", line 259, in wait
    raise MailboxError("transport failed")
wandb.errors.MailboxError: transport failed
